2025-07-28 09:58:03,723 ERROR: Error fetching DB records: 'str' object has no attribute 'isoformat' [in C:\mindai\backend\routes\admin_routes.py:590]
Traceback (most recent call last):
  File "C:\mindai\backend\routes\admin_routes.py", line 540, in get_db_records
    'timestamp': entry.get('created_at', datetime.datetime.utcnow()).isoformat(),
AttributeError: 'str' object has no attribute 'isoformat'
2025-07-28 09:58:08,260 INFO: DEBUG (get_my_menu_items): API called. Attempting to find menus for roles: ['관리자'] [in C:\mindai\backend\routes\admin_routes.py:57]
2025-07-28 09:58:08,272 INFO: DEBUG (get_my_menu_items): Found and returning 6 menu items. [in C:\mindai\backend\routes\admin_routes.py:83]
2025-07-28 09:58:11,677 INFO: DEBUG (get_my_menu_items): API called. Attempting to find menus for roles: ['관리자'] [in C:\mindai\backend\routes\admin_routes.py:57]
2025-07-28 09:58:11,680 INFO: DEBUG (get_my_menu_items): Found and returning 6 menu items. [in C:\mindai\backend\routes\admin_routes.py:83]
2025-07-28 09:58:13,128 INFO: DEBUG (get_my_menu_items): API called. Attempting to find menus for roles: ['관리자'] [in C:\mindai\backend\routes\admin_routes.py:57]
2025-07-28 09:58:13,132 INFO: DEBUG (get_my_menu_items): Found and returning 6 menu items. [in C:\mindai\backend\routes\admin_routes.py:83]
2025-07-28 09:58:22,498 INFO: DEBUG (get_my_menu_items): API called. Attempting to find menus for roles: ['관리자'] [in C:\mindai\backend\routes\admin_routes.py:57]
2025-07-28 09:58:22,505 INFO: DEBUG (get_my_menu_items): Found and returning 6 menu items. [in C:\mindai\backend\routes\admin_routes.py:83]
2025-07-28 09:58:24,377 INFO: DEBUG (get_my_menu_items): API called. Attempting to find menus for roles: ['관리자'] [in C:\mindai\backend\routes\admin_routes.py:57]
2025-07-28 09:58:24,382 INFO: DEBUG (get_my_menu_items): Found and returning 6 menu items. [in C:\mindai\backend\routes\admin_routes.py:83]
2025-07-28 09:58:28,952 INFO: DEBUG (get_my_menu_items): API called. Attempting to find menus for roles: ['관리자'] [in C:\mindai\backend\routes\admin_routes.py:57]
2025-07-28 09:58:28,957 INFO: DEBUG (get_my_menu_items): Found and returning 6 menu items. [in C:\mindai\backend\routes\admin_routes.py:83]
2025-07-28 09:58:34,411 INFO: DEBUG (get_my_menu_items): API called. Attempting to find menus for roles: ['관리자'] [in C:\mindai\backend\routes\admin_routes.py:57]
2025-07-28 09:58:34,416 INFO: DEBUG (get_my_menu_items): Found and returning 6 menu items. [in C:\mindai\backend\routes\admin_routes.py:83]
2025-07-28 09:58:46,290 ERROR: An unhandled exception occurred: Could not build url for endpoint 'community'. Did you mean 'community_list' instead? [in C:\mindai\backend\app.py:122]
Traceback (most recent call last):
  File "C:\Users\ADsThinkCentre\AppData\Local\Programs\Python\Python310\lib\site-packages\flask\app.py", line 823, in full_dispatch_request
    rv = self.dispatch_request()
  File "C:\Users\ADsThinkCentre\AppData\Local\Programs\Python\Python310\lib\site-packages\flask\app.py", line 808, in dispatch_request
    return self.ensure_sync(self.view_functions[rule.endpoint])(**view_args)  # type: ignore[no-any-return]
  File "C:\mindai\backend\app.py", line 188, in community_edit
    return render_template('community_edit.html', post_id=post_id)
  File "C:\Users\ADsThinkCentre\AppData\Local\Programs\Python\Python310\lib\site-packages\flask\templating.py", line 150, in render_template
    return _render(app, template, context)
  File "C:\Users\ADsThinkCentre\AppData\Local\Programs\Python\Python310\lib\site-packages\flask\templating.py", line 131, in _render
    rv = template.render(context)
  File "C:\Users\ADsThinkCentre\AppData\Local\Programs\Python\Python310\lib\site-packages\jinja2\environment.py", line 1304, in render
    self.environment.handle_exception()
  File "C:\Users\ADsThinkCentre\AppData\Local\Programs\Python\Python310\lib\site-packages\jinja2\environment.py", line 939, in handle_exception
    raise rewrite_traceback_stack(source=source)
  File "C:\mindai\frontend\templates\community_edit.html", line 1, in top-level template code
    {% extends "base.html" %}
  File "C:\mindai\frontend\templates\base.html", line 32, in top-level template code
    {% block content %}{% endblock %}
  File "C:\mindai\frontend\templates\community_edit.html", line 74, in block 'content'
    const communityListUrl = "{{ url_for('community') }}";
  File "C:\Users\ADsThinkCentre\AppData\Local\Programs\Python\Python310\lib\site-packages\flask\app.py", line 1027, in url_for
    return self.handle_url_build_error(error, endpoint, values)
  File "C:\Users\ADsThinkCentre\AppData\Local\Programs\Python\Python310\lib\site-packages\flask\app.py", line 1016, in url_for
    rv = url_adapter.build(  # type: ignore[union-attr]
  File "C:\Users\ADsThinkCentre\AppData\Local\Programs\Python\Python310\lib\site-packages\werkzeug\routing\map.py", line 924, in build
    raise BuildError(endpoint, values, method, self)
werkzeug.routing.exceptions.BuildError: Could not build url for endpoint 'community'. Did you mean 'community_list' instead?
2025-07-28 09:58:46,310 ERROR: Exception on /community/edit/3 [GET] [in C:\Users\ADsThinkCentre\AppData\Local\Programs\Python\Python310\lib\site-packages\flask\app.py:781]
Traceback (most recent call last):
  File "C:\Users\ADsThinkCentre\AppData\Local\Programs\Python\Python310\lib\site-packages\flask\app.py", line 823, in full_dispatch_request
    rv = self.dispatch_request()
  File "C:\Users\ADsThinkCentre\AppData\Local\Programs\Python\Python310\lib\site-packages\flask\app.py", line 808, in dispatch_request
    return self.ensure_sync(self.view_functions[rule.endpoint])(**view_args)  # type: ignore[no-any-return]
  File "C:\mindai\backend\app.py", line 188, in community_edit
    return render_template('community_edit.html', post_id=post_id)
  File "C:\Users\ADsThinkCentre\AppData\Local\Programs\Python\Python310\lib\site-packages\flask\templating.py", line 150, in render_template
    return _render(app, template, context)
  File "C:\Users\ADsThinkCentre\AppData\Local\Programs\Python\Python310\lib\site-packages\flask\templating.py", line 131, in _render
    rv = template.render(context)
  File "C:\Users\ADsThinkCentre\AppData\Local\Programs\Python\Python310\lib\site-packages\jinja2\environment.py", line 1304, in render
    self.environment.handle_exception()
  File "C:\Users\ADsThinkCentre\AppData\Local\Programs\Python\Python310\lib\site-packages\jinja2\environment.py", line 939, in handle_exception
    raise rewrite_traceback_stack(source=source)
  File "C:\mindai\frontend\templates\community_edit.html", line 1, in top-level template code
    {% extends "base.html" %}
  File "C:\mindai\frontend\templates\base.html", line 32, in top-level template code
    {% block content %}{% endblock %}
  File "C:\mindai\frontend\templates\community_edit.html", line 74, in block 'content'
    const communityListUrl = "{{ url_for('community') }}";
  File "C:\Users\ADsThinkCentre\AppData\Local\Programs\Python\Python310\lib\site-packages\flask\app.py", line 1027, in url_for
    return self.handle_url_build_error(error, endpoint, values)
  File "C:\Users\ADsThinkCentre\AppData\Local\Programs\Python\Python310\lib\site-packages\flask\app.py", line 1016, in url_for
    rv = url_adapter.build(  # type: ignore[union-attr]
  File "C:\Users\ADsThinkCentre\AppData\Local\Programs\Python\Python310\lib\site-packages\werkzeug\routing\map.py", line 924, in build
    raise BuildError(endpoint, values, method, self)
werkzeug.routing.exceptions.BuildError: Could not build url for endpoint 'community'. Did you mean 'community_list' instead?

During handling of the above exception, another exception occurred:

Traceback (most recent call last):
  File "C:\Users\ADsThinkCentre\AppData\Local\Programs\Python\Python310\lib\site-packages\flask\app.py", line 1417, in wsgi_app
    response = self.full_dispatch_request()
  File "C:\Users\ADsThinkCentre\AppData\Local\Programs\Python\Python310\lib\site-packages\flask\app.py", line 825, in full_dispatch_request
    rv = self.handle_user_exception(e)
  File "C:\Users\ADsThinkCentre\AppData\Local\Programs\Python\Python310\lib\site-packages\flask_cors\extension.py", line 176, in wrapped_function
    return cors_after_request(app.make_response(f(*args, **kwargs)))
  File "C:\Users\ADsThinkCentre\AppData\Local\Programs\Python\Python310\lib\site-packages\flask\app.py", line 715, in handle_user_exception
    return self.ensure_sync(handler)(e)  # type: ignore[no-any-return]
  File "C:\mindai\backend\app.py", line 127, in handle_exception
    return render_template('500.html', error_message=str(e)), 500 # 500.html이 없으므로 임시로 에러 메시지 직접 표시
  File "C:\Users\ADsThinkCentre\AppData\Local\Programs\Python\Python310\lib\site-packages\flask\templating.py", line 149, in render_template
    template = app.jinja_env.get_or_select_template(template_name_or_list)
  File "C:\Users\ADsThinkCentre\AppData\Local\Programs\Python\Python310\lib\site-packages\jinja2\environment.py", line 1084, in get_or_select_template
    return self.get_template(template_name_or_list, parent, globals)
  File "C:\Users\ADsThinkCentre\AppData\Local\Programs\Python\Python310\lib\site-packages\jinja2\environment.py", line 1013, in get_template
    return self._load_template(name, globals)
  File "C:\Users\ADsThinkCentre\AppData\Local\Programs\Python\Python310\lib\site-packages\jinja2\environment.py", line 972, in _load_template
    template = self.loader.load(self, name, self.make_globals(globals))
  File "C:\Users\ADsThinkCentre\AppData\Local\Programs\Python\Python310\lib\site-packages\jinja2\loaders.py", line 126, in load
    source, filename, uptodate = self.get_source(environment, name)
  File "C:\Users\ADsThinkCentre\AppData\Local\Programs\Python\Python310\lib\site-packages\flask\templating.py", line 65, in get_source
    return self._get_source_fast(environment, template)
  File "C:\Users\ADsThinkCentre\AppData\Local\Programs\Python\Python310\lib\site-packages\flask\templating.py", line 99, in _get_source_fast
    raise TemplateNotFound(template)
jinja2.exceptions.TemplateNotFound: 500.html
