2025-07-28 09:59:52,645 ERROR: Error fetching analytics diary entry counts: PlanExecutor error during aggregation :: caused by :: $dateToString parameter 'date' must be coercible to date, full error: {'ok': 0.0, 'errmsg': "PlanExecutor error during aggregation :: caused by :: $dateToString parameter 'date' must be coercible to date", 'code': 4997901, 'codeName': 'Location4997901'} [in C:\mindai\backend\routes\admin_routes.py:975]
Traceback (most recent call last):
  File "C:\mindai\backend\routes\admin_routes.py", line 958, in get_analytics_diary_entry_counts
    results = list(mongo.db.diary_entries.aggregate(pipeline))
  File "C:\Users\ADsThinkCentre\AppData\Local\Programs\Python\Python310\lib\site-packages\pymongo\synchronous\collection.py", line 2979, in aggregate
    return self._aggregate(
  File "C:\Users\ADsThinkCentre\AppData\Local\Programs\Python\Python310\lib\site-packages\pymongo\_csot.py", line 125, in csot_wrapper
    return func(self, *args, **kwargs)
  File "C:\Users\ADsThinkCentre\AppData\Local\Programs\Python\Python310\lib\site-packages\pymongo\synchronous\collection.py", line 2886, in _aggregate
    return self._database.client._retryable_read(
  File "C:\Users\ADsThinkCentre\AppData\Local\Programs\Python\Python310\lib\site-packages\pymongo\synchronous\mongo_client.py", line 2026, in _retryable_read
    return self._retry_internal(
  File "C:\Users\ADsThinkCentre\AppData\Local\Programs\Python\Python310\lib\site-packages\pymongo\_csot.py", line 125, in csot_wrapper
    return func(self, *args, **kwargs)
  File "C:\Users\ADsThinkCentre\AppData\Local\Programs\Python\Python310\lib\site-packages\pymongo\synchronous\mongo_client.py", line 1993, in _retry_internal
    ).run()
  File "C:\Users\ADsThinkCentre\AppData\Local\Programs\Python\Python310\lib\site-packages\pymongo\synchronous\mongo_client.py", line 2730, in run
    return self._read() if self._is_read else self._write()
  File "C:\Users\ADsThinkCentre\AppData\Local\Programs\Python\Python310\lib\site-packages\pymongo\synchronous\mongo_client.py", line 2891, in _read
    return self._func(self._session, self._server, conn, read_pref)  # type: ignore
  File "C:\Users\ADsThinkCentre\AppData\Local\Programs\Python\Python310\lib\site-packages\pymongo\synchronous\aggregation.py", line 164, in get_cursor
    result = conn.command(
  File "C:\Users\ADsThinkCentre\AppData\Local\Programs\Python\Python310\lib\site-packages\pymongo\synchronous\helpers.py", line 47, in inner
    return func(*args, **kwargs)
  File "C:\Users\ADsThinkCentre\AppData\Local\Programs\Python\Python310\lib\site-packages\pymongo\synchronous\pool.py", line 414, in command
    return command(
  File "C:\Users\ADsThinkCentre\AppData\Local\Programs\Python\Python310\lib\site-packages\pymongo\synchronous\network.py", line 212, in command
    helpers_shared._check_command_response(
  File "C:\Users\ADsThinkCentre\AppData\Local\Programs\Python\Python310\lib\site-packages\pymongo\helpers_shared.py", line 250, in _check_command_response
    raise OperationFailure(errmsg, code, response, max_wire_version)
pymongo.errors.OperationFailure: PlanExecutor error during aggregation :: caused by :: $dateToString parameter 'date' must be coercible to date, full error: {'ok': 0.0, 'errmsg': "PlanExecutor error during aggregation :: caused by :: $dateToString parameter 'date' must be coercible to date", 'code': 4997901, 'codeName': 'Location4997901'}
2025-07-28 09:59:58,120 INFO: DEBUG (get_my_menu_items): API called. Attempting to find menus for roles: ['°ü¸®ÀÚ'] [in C:\mindai\backend\routes\admin_routes.py:57]
2025-07-28 09:59:58,126 INFO: DEBUG (get_my_menu_items): Found and returning 6 menu items. [in C:\mindai\backend\routes\admin_routes.py:83]
2025-07-28 09:59:58,923 ERROR: An unhandled exception occurred: chatbot_feedback.html [in C:\mindai\backend\app.py:122]
Traceback (most recent call last):
  File "C:\Users\ADsThinkCentre\AppData\Local\Programs\Python\Python310\lib\site-packages\flask\app.py", line 823, in full_dispatch_request
    rv = self.dispatch_request()
  File "C:\Users\ADsThinkCentre\AppData\Local\Programs\Python\Python310\lib\site-packages\flask\app.py", line 808, in dispatch_request
    return self.ensure_sync(self.view_functions[rule.endpoint])(**view_args)  # type: ignore[no-any-return]
  File "C:\mindai\backend\app.py", line 229, in chatbot_feedback
    return render_template('chatbot_feedback.html')
  File "C:\Users\ADsThinkCentre\AppData\Local\Programs\Python\Python310\lib\site-packages\flask\templating.py", line 149, in render_template
    template = app.jinja_env.get_or_select_template(template_name_or_list)
  File "C:\Users\ADsThinkCentre\AppData\Local\Programs\Python\Python310\lib\site-packages\jinja2\environment.py", line 1084, in get_or_select_template
    return self.get_template(template_name_or_list, parent, globals)
  File "C:\Users\ADsThinkCentre\AppData\Local\Programs\Python\Python310\lib\site-packages\jinja2\environment.py", line 1013, in get_template
    return self._load_template(name, globals)
  File "C:\Users\ADsThinkCentre\AppData\Local\Programs\Python\Python310\lib\site-packages\jinja2\environment.py", line 972, in _load_template
    template = self.loader.load(self, name, self.make_globals(globals))
  File "C:\Users\ADsThinkCentre\AppData\Local\Programs\Python\Python310\lib\site-packages\jinja2\loaders.py", line 126, in load
    source, filename, uptodate = self.get_source(environment, name)
  File "C:\Users\ADsThinkCentre\AppData\Local\Programs\Python\Python310\lib\site-packages\flask\templating.py", line 65, in get_source
    return self._get_source_fast(environment, template)
  File "C:\Users\ADsThinkCentre\AppData\Local\Programs\Python\Python310\lib\site-packages\flask\templating.py", line 99, in _get_source_fast
    raise TemplateNotFound(template)
jinja2.exceptions.TemplateNotFound: chatbot_feedback.html
